Traceback (most recent call last):
  File "/home/lw/venv-ngbem/lib/python3.12/site-packages/jupyter_cache/executors/utils.py", line 58, in single_nb_execution
    executenb(
  File "/home/lw/venv-ngbem/lib/python3.12/site-packages/nbclient/client.py", line 1314, in execute
    return NotebookClient(nb=nb, resources=resources, km=km, **kwargs).execute()
           ^^^^^^^^^^^^^^^^^^^^^^^^^^^^^^^^^^^^^^^^^^^^^^^^^^^^^^^^^^^^^^^^^^^^^
  File "/home/lw/venv-ngbem/lib/python3.12/site-packages/jupyter_core/utils/__init__.py", line 165, in wrapped
    return loop.run_until_complete(inner)
           ^^^^^^^^^^^^^^^^^^^^^^^^^^^^^^
  File "/usr/lib/python3.12/asyncio/base_events.py", line 687, in run_until_complete
    return future.result()
           ^^^^^^^^^^^^^^^
  File "/home/lw/venv-ngbem/lib/python3.12/site-packages/nbclient/client.py", line 709, in async_execute
    await self.async_execute_cell(
  File "/home/lw/venv-ngbem/lib/python3.12/site-packages/nbclient/client.py", line 1062, in async_execute_cell
    await self._check_raise_for_error(cell, cell_index, exec_reply)
  File "/home/lw/venv-ngbem/lib/python3.12/site-packages/nbclient/client.py", line 918, in _check_raise_for_error
    raise CellExecutionError.from_cell_and_msg(cell, exec_reply_content)
nbclient.exceptions.CellExecutionError: An error occurred while executing the following cell:
------------------
with TaskManager(): 
    V1 = HelmholtzSL( uHDiv.Trace()*ds(bonus_intorder=6) , kappa) * vHDiv.Trace() * ds(bonus_intorder=6)
    V2 = HelmholtzSL( div(uHDiv.Trace()) * ds(bonus_intorder=6), kappa) * div(vHDiv.Trace()) * ds(bounus_intorder=6)
    V = kappa * V1.mat - 1/kappa * V2.mat
------------------


[0;31m---------------------------------------------------------------------------[0m
[0;31mTypeError[0m                                 Traceback (most recent call last)
Cell [0;32mIn[6], line 3[0m
[1;32m      1[0m [38;5;28;01mwith[39;00m TaskManager(): 
[1;32m      2[0m     V1 [38;5;241m=[39m HelmholtzSL( uHDiv[38;5;241m.[39mTrace()[38;5;241m*[39mds(bonus_intorder[38;5;241m=[39m[38;5;241m6[39m) , kappa) [38;5;241m*[39m vHDiv[38;5;241m.[39mTrace() [38;5;241m*[39m ds(bonus_intorder[38;5;241m=[39m[38;5;241m6[39m)
[0;32m----> 3[0m     V2 [38;5;241m=[39m HelmholtzSL( div(uHDiv[38;5;241m.[39mTrace()) [38;5;241m*[39m ds(bonus_intorder[38;5;241m=[39m[38;5;241m6[39m), kappa) [38;5;241m*[39m div(vHDiv[38;5;241m.[39mTrace()) [38;5;241m*[39m [43mds[49m[43m([49m[43mbounus_intorder[49m[38;5;241;43m=[39;49m[38;5;241;43m6[39;49m[43m)[49m
[1;32m      4[0m     V [38;5;241m=[39m kappa [38;5;241m*[39m V1[38;5;241m.[39mmat [38;5;241m-[39m [38;5;241m1[39m[38;5;241m/[39mkappa [38;5;241m*[39m V2[38;5;241m.[39mmat

[0;31mTypeError[0m: __call__(): incompatible function arguments. The following argument types are supported:
    1. (self: ngsolve.comp.DifferentialSymbol, definedon: Optional[Union[ngsolve.comp.Region, str]] = None, element_boundary: bool = False, element_vb: ngsolve.comp.VorB = <VorB.VOL: 0>, skeleton: bool = False, bonus_intorder: int = 0, intrules: dict[ngsolve.fem.ET, ngsolve.fem.IntegrationRule] = {}, deformation: ngsolve.comp.GridFunction = None, definedonelements: pyngcore.pyngcore.BitArray = None) -> ngsolve.comp.DifferentialSymbol

Invoked with: <ngsolve.comp.DifferentialSymbol object at 0x7e6f50643030>; kwargs: bounus_intorder=6

